Workbook

Sheet Costos Insumos
A1: Cógido | B1: Nombre | C1: Tipo de producto | D1: Unidad de medida | E1: Costo x unidad | F1: Fecha actualización costo
B2: Costo PEROXIDO LUPEROX K12G | C2: MS | E2: =513/13.5 -> 38
A3: CMPD01-0016-000-0000 | B3: PEROXIDO REVOX HD-50(REVOX HD) - Para todo menos Gelcoat Gris FV y RTM | D3: GR | E3: 35.2 | F3: 26/05/2025
A4: PINP01-0006-000-0000 | B4: MEZCLA POLIMERO COLADO | C4: MS | D4: KG | E4: 2518.68 | F4: 46043
A5: CMPD01-0022-000-0000 | B5: GELCOAT BLANCO 898GC/ 5-2899W | C5: MS | E5: 18050 | F5: 46043
A6: PGEL01-0008-000-0508 | B6: GELCOAT BLANCO FORT | C6: MS | D6: KG | E6: 20127 | F6: 26/05/2025
B7: Costo KG Perla | C7: MS | E7: =(12553.02+12631.52)/2 -> 12592.27
A8: CEMP03-0426-000-0000 | B8: LAMINA CARTON 1.15X2MT CALIBRE E450 E-MICROCORRUGADO ESTAMPADO PARA CAJAS MS | C8: MS | E8: 6135 | F8: 26/05/2025
A9: PZCO01-0001-000-0000 | B9: MANO OBRA POR MIN MARMOL SINTETICO | C9: MS | D9: MIN | E9: 327 | F9: 26/05/2025 | Y9: 0 | AA9: Manual | AB9: NO | AD9: N/A | AE9: No | AF9: No | AH9: FINANZAS | AI9: 0 | AJ9: MIN | AK9: 21/01/2025 | AL9: SIN MOLDE | AP9: MIN | AS9: No | AT9: Finanzas | AU9: ZCO01 | AV9: 0 | AW9: No | AX9: NO | AY9: 1 | AZ9: Sí | BA9: 0.01 | BB9: 0.01 | BC9: 0.01 | BD9: 1
A10: PZCO01-0011-000-0000 | B10: MANO OBRA POR MIN FIBRA DE VIDRIO | C10: FV | D10: MIN | E10: 332 | F10: 26/05/2025 | Y10: 0 | AA10: Manual | AB10: NO | AD10: N/A | AE10: No | AF10: No | AH10: FINANZAS | AI10: 0 | AJ10: MIN | AK10: 21/01/2025 | AL10: SIN MOLDE | AP10: MIN | AS10: No | AT10: Finanzas | AU10: ZCO01 | AV10: 0 | AW10: No | AX10: NO | AY10: 1 | AZ10: Sí | BA10: 0.01 | BB10: 0.01 | BC10: 0.01 | BD10: 1
A11: PZCO01-0012-000-0000 | B11: MANO OBRA POR MIN RTM LIGHT | C11: RTM | D11: MIN | E11: 340 | F11: 26/05/2025 | Y11: 0 | AA11: Manual | AB11: NO | AD11: N/A | AE11: No | AF11: No | AH11: FINANZAS | AI11: 0 | AJ11: MIN | AK11: 21/01/2025 | AL11: SIN MOLDE | AP11: MIN | AS11: No | AT11: Finanzas | AU11: ZCO01 | AV11: 0 | AW11: No | AX11: NO | AY11: 1 | AZ11: Sí | BA11: 0.01 | BB11: 0.01 | BC11: 0.01 | BD11: 1
A12: PZCO01-0013-000-0000 | B12: MANO OBRA POR MIN PLANTA AMBIENTAL | D12: MIN | E12: 181 | F12: 26/05/2025 | Y12: 0 | AA12: Manual | AB12: NO | AD12: N/A | AE12: No | AF12: No | AH12: FINANZAS | AI12: 0 | AJ12: MIN | AK12: 13/09/2023 | AP12: MIN | AS12: No | AT12: Finanzas | AU12: ZCO01 | AV12: 0 | AW12: No | AX12: NO | AY12: 1 | AZ12: Sí | BA12: 0.01 | BB12: 0.01 | BC12: 0.01 | BD12: 1
A13: PZCO01-0014-000-0000 | B13: MANO OBRA POR MIN MUEBLES | C13: MBL | D13: MIN | E13: 305 | F13: 26/05/2025 | Y13: 0 | AA13: Manual | AB13: NO | AD13: N/A | AE13: No | AF13: No | AH13: FINANZAS | AI13: 0 | AJ13: MIN | AK13: 21/01/2025 | AL13: SIN MOLDE | AP13: MIN | AS13: No | AT13: Finanzas | AU13: ZCO01 | AV13: 0 | AW13: No | AX13: NO | AY13: 1 | AZ13: Sí | BA13: 0.01 | BB13: 0.01 | BC13: 0.01 | BD13: 1
A14: PZCO01-0023-000-0000 | B14: MANO OBRA POR MIN CEFI | C14: CEFI | D14: MIN | E14: 313 | F14: 26/05/2025 | Y14: 0 | AA14: Manual | AB14: NO | AD14: N/A | AE14: No | AF14: No | AH14: FINANZAS | AI14: 0 | AJ14: MIN | AK14: 21/01/2025 | AL14: SIN MOLDE | AP14: MIN | AS14: No | AT14: Finanzas | AU14: ZCO01 | AV14: 0 | AW14: No | AX14: NO | AY14: 1 | AZ14: Sí | BA14: 0.01 | BB14: 0.01 | BC14: 0.01 | BD14: 1
A15: PZCO01-0002-000-0000 | B15: CIF POR MINUTO | C15: MS, FV | E15: 638 | F15: 26/05/2025
A16: PZCO01-0015-000-0000 | B16: CIF POR MINUTO MUEBLES | C16: MBL | E16: 974 | F16: 26/05/2025
A17: PZCO01-0024-000-0000 | B17: CIF POR MINUTO CEFI | C17: CEFI | E17: 1756 | F17: 26/05/2025
A18: PZCO01-0004-000-0000 | B18: CIF POR MINUTO MOLDES | C18: MOLDES | E18: 78 | F18: 26/05/2025
A19: CEMP02-0226-000-0000 | B19: ETIQUETA REVISION CALIDAD PC | C19: MS | E19: 135 | F19: 26/05/2025
A20: CEMP03-0307-000-0000 | B20: ETIQUETA ADHESIVA SIN IMPRESION 100X200MM | C20: MS | E20: 69.3 | F20: 26/05/2025
A21: CEMP02-0363-000-0000 | B21: HONEYCOMB 30X7.5X3.1CM 540 - HCC W 26_27W - L240 | C21: Empaque MS | D21: UN | E21: 670 | F21: 26/05/2025
B22: LISTON HCC 10.6 E 4CM * A 6CM * L 30CM / L240 - L240 | E22: 540
A23: CEMP02-0042-000-0000 | B23: CAJA MESON ECO 150x55CM | C23: Empaque MS | D23: UN | E23: 4292.53 | F23: 26/05/2025
B24: INSTRUCCIONES | C24: MS
B25: LAMINA CARTON 4 MM | C25: MS
A26: CMPD03-0007-000-0000 | B26: FIBRA DE VIDRIO PICADA | D26: GR | E26: =10460/1000 -> 10.46 | F26: 26/05/2025
A27: COMP02-0033-000-0000 | B27: TUERCA 12MM P1.75 HEXAGONAL PARA HERRAJES | D27: KG | E27: 293.14
A28: CMPD07-0012-000-0000 | B28: TORNILLO ENSAMBLE 6X1IN | E28: 19.27
A29: CMPD04-0002-000-0000 | B29: TAPA TORNILLO PLAST 9MM (DAMA SENCILLA) BLANCA | E29: 16.81
A30: CMPD04-0044-000-0000 | B30: SNAP FIJACION FALDON | E30: 1107.48
A31: CMPD04-0045-000-0000 | B31: L FIJACION FALDON ACH | E31: 916.63
A32: COMP02-0028-000-0000 | B32: TUBO C18 3/4IN MECANICO CUADRADO GALVANIZADO | E32: 1611.5
A33: CEMP02-0113-000-0000 | B33: CARTON SINGLE FACE 20CM | E33: 241.47
A34: PINP01-0004-000-0000 | B34: REFUERZO FIBRA VIDRIO CON RESINA CARGADA Y CATALIZADOR | E34: 8051.21
A35: PINP01-0005-000-0000 | B35: REFUERZO FIBRA VIDRIO CON RESINA SIN CARGA Y CATALIZADOR | E35: 8984.97
A36: CMPD01-0022-000-0000 | B36: GELCOAT BLANCO 898GC/ 5-2899W | E36: 18050
A37: CMPD01-0017-000-0000 | B37: PEROXIDO LUPEROX K12G | E37: 37.93
A38: PINP01-0007-000-0000 | B38: MASILLA PARA VACIADO | E38: 7203.88
A39: CEMP02-0208-000-0000 | B39: CAJA LVM MULTIPLE 124X48 | E39: 11919

Sheet Mármol Sintético
A1: Código | B1: Referencia | C1: Volumen (mm^3) | D1: Mezcla Polimero colado (kg) | E1: Costo Mezcla ($) | F1: Área superficial (mm^2) | G1: Gelcoat (kg) | H1: Costo Gelcoat ($) | I1: Peroxido (gr) | J1: Costo peroxido | K1: Empaque | L1: Etiqueta calidad + Intructivo | M1: Otros | N1: Costo producto MP Apróximado sin MO ni CIF ($) | O1: MC% | P1: Precio Mínimo | Q1: Descuento | R1: Precio Maximo | S1: PVP | U1: Peso neto (kg) | V1: Peso bruto (kg)
B2: LVR VERSA 50X50 | C2: 3017000 | D2: 8 | E2: =D2*'Costos Insumos'!$E$4 -> 20149.44 | F2: =828200/2 -> 414100 | G2: =(F2*$G$3)/$F$3 -> 0.46554244 | H2: ='Costos Insumos'!$E$5*G2 -> 8403.041 | I2: =(G2*1000)*2.5% -> 11.638561 | J2: =((G2*1000)*2.5%)*'Costos Insumos'!$E$2 -> 442.26532 | K2: 2000 | L2: 114.35 | N2: 27517.171 | O2: 0.67 | P2: =N2/(1-O2) -> 83385.366 | Q2: 0.4 | R2: =P2/(1-Q2) -> 138975.61 | S2: =(P2/0.75)*1.19 -> 132304.78
B3: LVM OSLO 48X38 (REAL) | C3: 2270000 | D3: 6.2 | E3: =D3*'Costos Insumos'!$E$4 -> 15615.816 | F3: 355800 | G3: =400/1000 -> 0.4 | H3: ='Costos Insumos'!$E$5*G3 -> 7220 | I3: =(G3*1000)*2.5% -> 10 | J3: =((G3*1000)*2.5%)*'Costos Insumos'!$E$2 -> 380 | K3: 2100 | L3: 114.35 | N3: 27517.171 | O3: 0.818 | P3: =N3/(1-O3) -> 151193.25 | Q3: 0.4 | R3: =P3/(1-Q3) -> 251988.74 | S3: =(P3/0.75)*1.19 -> 239893.29
B4: LVM VESSEL DOHA | C4: =1439000 -> 1439000 | D4: =(C4*$D$3)/$C$3 -> 3.9303084 | E4: =D4*'Costos Insumos'!$E$4 -> 9899.1891 | F4: 257700 | G4: =(F4*$G$3)/$F$3 -> 0.28971332 | H4: ='Costos Insumos'!$E$5*G4 -> 5229.3255 | I4: =(G4*1000)*2.5% -> 7.2428331 | J4: =((G4*1000)*2.5%)*'Costos Insumos'!$E$2 -> 275.22766 | K4: =('Costos Insumos'!$E$8/3)+(67*4) -> 2313 | L4: 119.08 | N4: =E4+H4+K4+L4 -> 17560.595 | O4: 0.75 | P4: =N4/(1-O4) -> 70242.378 | Q4: 0.4 | R4: =P4/(1-Q4) -> 117070.63 | S4: =(P4/0.75)*1.19 -> 111451.24 | U4: 4.31 | V4: 4.38
B5: LVM VESSEL DOHA (REAL) | C5: =1439000 -> 1439000 | D5: 4 | E5: =D5*'Costos Insumos'!$E$4 -> 10074.72 | F5: 257700 | G5: 0.4 | H5: ='Costos Insumos'!$E$5*G5 -> 7220 | I5: =(G5*1000)*2.5% -> 10 | J5: =((G5*1000)*2.5%)*'Costos Insumos'!$E$2 -> 380 | K5: =('Costos Insumos'!$E$8/3)+(67*4) -> 2313 | L5: 119.08 | N5: =E5+H5+K5+L5 -> 19726.8 | O5: 0.75 | P5: =N5/(1-O5) -> 78907.2 | Q5: 0.4 | R5: =P5/(1-Q5) -> 131512 | S5: =(P5/0.75)*1.19 -> 125199.42 | U5: 4.31 | V5: 4.38
B6: Meson Oasis 63x48 | C6: 1928000 | D6: =(C6*$D$3)/$C$3 -> 5.2659031 | E6: =D6*'Costos Insumos'!$E$4 -> 13263.125 | F6: 279000 | G6: =(F6*$G$3)/$F$3 -> 0.31365936 | H6: ='Costos Insumos'!$E$5*G6 -> 5661.5514 | I6: =(G6*1000)*2.5% -> 7.841484 | J6: =((G6*1000)*2.5%)*'Costos Insumos'!$E$2 -> 297.97639 | K6: =('Costos Insumos'!$E$8/3)+(67*4)+3152 -> 5465 | L6: 119.08 | N6: =E6+H6+K6+L6 -> 24508.756 | O6: 0.75 | P6: =N6/(1-O6) -> 98035.025 | Q6: 0.4 | R6: =P6/(1-Q6) -> 163391.71 | S6: =(P6/0.75)*1.19 -> 155548.91
B7: Meson Oasis 63x48 (REAL) | C7: 1928000 | D7: 6 | E7: =D7*'Costos Insumos'!$E$4 -> 15112.08 | F7: 279000 | G7: 0.46 | H7: ='Costos Insumos'!$E$5*G7 -> 8303 | I7: =(G7*1000)*2.5% -> 11.5 | J7: =((G7*1000)*2.5%)*'Costos Insumos'!$E$2 -> 437 | K7: =('Costos Insumos'!$E$8/3)+(67*4)+3152 -> 5465 | L7: 119.08 | N7: =E7+H7+K7+L7 -> 28999.16 | O7: 0.75 | P7: =N7/(1-O7) -> 115996.64 | Q7: 0.4 | R7: =P7/(1-Q7) -> 193327.73 | S7: =(P7/0.75)*1.19 -> 184048
B8: Lavamanos Meca Vessel 35x35 | C8: 1519000 | D8: =(C8*$D$3)/$C$3 -> 4.1488106 | E8: =D8*'Costos Insumos'!$E$4 -> 10449.526 | F8: 238200 | G8: =(F8*$G$3)/$F$3 -> 0.26779089 | H8: ='Costos Insumos'!$E$5*G8 -> 4833.6256 | I8: =(G8*1000)*2.5% -> 6.6947723 | J8: =((G8*1000)*2.5%)*'Costos Insumos'!$E$2 -> 254.40135 | K8: =('Costos Insumos'!$E$8/3)+(67*4) -> 2313 | L8: 119.08 | N8: =E8+H8+K8+L8 -> 17715.232 | O8: 0.8 | P8: =N8/(1-O8) -> 88576.159 | Q8: 0.4 | R8: =P8/(1-Q8) -> 147626.93 | S8: =(P8/0.75)*1.19 -> 140540.84 | U8: =(U4*D4)/D8 -> 4.0830086 | V8: =(U8*V4)/U4 -> 4.1493219
B9: Lavamanos Meca Vessel 35x35 (REAL) | C9: 1850000 | D9: 4 | E9: =D9*'Costos Insumos'!$E$4 -> 10074.72 | F9: 238200 | G9: 0.37 | H9: ='Costos Insumos'!$E$5*G9 -> 6678.5 | I9: =(G9*1000)*2.5% -> 9.25 | J9: =((G9*1000)*2.5%)*'Costos Insumos'!$E$2 -> 351.5 | K9: =('Costos Insumos'!$E$8/3)+(67*4) -> 2313 | L9: 119.08 | N9: =E9+H9+K9+L9 -> 19185.3 | O9: 0.8 | P9: =N9/(1-O9) -> 95926.5 | Q9: 0.4 | R9: =P9/(1-Q9) -> 159877.5 | S9: =(P9/0.75)*1.19 -> 152203.38
B10: Placa Genova 63x48 | C10: 228300 | D10: =(C10*$D$3)/$C$3 -> 0.62355066 | E10: =D10*'Costos Insumos'!$E$4 -> 1570.5246 | F10: 48168.2 | G10: =(F10*$G$3)/$F$3 -> 0.054151996 | H10: ='Costos Insumos'!$E$5*G10 -> 977.44352 | I10: =(G10*1000)*2.5% -> 1.3537999 | J10: =((G10*1000)*2.5%)*'Costos Insumos'!$E$2 -> 51.444396 | K10: 0 | L10: 0 | N10: =E10+H10+K10+L10 -> 2547.9681 | O10: 0.8 | P10: =N10/(1-O10) -> 12739.84 | Q10: 0.4 | R10: =P10/(1-Q10) -> 21233.067 | S10: =(P10/0.75)*1.19 -> 20213.88 | U10: =(U5*D5)/D10 -> 27.648114 | V10: =(U10*V5)/U5 -> 28.097156
B11: Placa Genova 79x48 | C11: 228300 | D11: =(C11*$D$3)/$C$3 -> 0.62355066 | E11: =D11*'Costos Insumos'!$E$4 -> 1570.5246 | F11: 48168.2 | G11: =(F11*$G$3)/$F$3 -> 0.054151996 | H11: ='Costos Insumos'!$E$5*G11 -> 977.44352 | I11: =(G11*1000)*2.5% -> 1.3537999 | J11: =((G11*1000)*2.5%)*'Costos Insumos'!$E$2 -> 51.444396 | K11: 0 | L11: 0 | N11: =E11+H11+K11+L11 -> 2547.9681 | O11: 0.8 | P11: =N11/(1-O11) -> 12739.84 | Q11: 0.4 | R11: =P11/(1-Q11) -> 21233.067 | S11: =(P11/0.75)*1.19 -> 20213.88 | U11: =(U6*D6)/D11 -> 0 | V11: =(U11*V6)/U6 -> #DIV/0!
B12: Piso ducha 183x86.5 | C12: 32860000 | D12: =(C12*$D$3)/$C$3 -> 89.74978 | E12: =D12*'Costos Insumos'!$E$4 -> 226050.98 | F12: 1705000 | G12: =(F12*$G$3)/$F$3 -> 1.9168072 | H12: ='Costos Insumos'!$E$5*G12 -> 34598.37 | I12: =(G12*1000)*2.5% -> 47.92018 | J12: =((G12*1000)*2.5%)*'Costos Insumos'!$E$2 -> 1820.9668 | K12: =('Costos Insumos'!$E$8*2)+(67*4)+20000 -> 32538 | L12: 119.08 | N12: =E12+H12+K12+L12 -> 293306.43 | O12: 0.68 | P12: =N12/(1-O12) -> 916582.58 | Q12: 0.4 | R12: =P12/(1-Q12) -> 1527637.6 | S12: =(P12/0.75)*1.19 -> 1454311
B13: Piso ducha 152.5x86.5 | C13: 27330000 | D13: =(C13*$D$3)/$C$3 -> 74.645815 | E13: =D13*'Costos Insumos'!$E$4 -> 188008.92 | F13: 1427000 | G13: =(F13*$G$3)/$F$3 -> 1.6042721 | H13: ='Costos Insumos'!$E$5*G13 -> 28957.111 | I13: =(G13*1000)*2.5% -> 40.106802 | J13: =((G13*1000)*2.5%)*'Costos Insumos'!$E$2 -> 1524.0585 | K13: =('Costos Insumos'!$E$8*2)+(67*4)+20000 -> 32538 | L13: 119.08 | N13: =E13+H13+K13+L13 -> 249623.11 | O13: 0.68 | P13: =N13/(1-O13) -> 780072.23 | Q13: 0.4 | R13: =P13/(1-Q13) -> 1300120.4 | S13: =(P13/0.75)*1.19 -> 1237714.6
B14: LVM OSLO 184,5x57,5 | C14: 13310000 | D14: =(C14*$D$3)/$C$3 -> 36.353304 | E14: =D14*'Costos Insumos'!$E$4 -> 91562.34 | F14: 1646000 | G14: =(F14*$G$3)/$F$3 -> 1.8504778 | H14: ='Costos Insumos'!$E$5*G14 -> 33401.124 | I14: =(G14*1000)*2.5% -> 46.261945 | J14: =((G14*1000)*2.5%)*'Costos Insumos'!$E$2 -> 1757.9539 | K14: =('Costos Insumos'!$E$8*2)+(67*4)+20000 -> 32538 | L14: 119.08 | N14: =E14+H14+K14+L14 -> 157620.54 | O14: 0.68 | P14: =N14/(1-O14) -> 492564.2 | Q14: 0.4 | R14: =P14/(1-Q14) -> 820940.33 | S14: =(P14/0.75)*1.19 -> 781535.2
B15: LVR VERSA 55X50 - Calculo 3D | C15: 3416000 | D15: =(C15*$D$27)/$C$27 -> 8.2896581 | E15: =D15*'Costos Insumos'!$E$4 -> 20878.996 | F15: 482700 | G15: =(F15*$G$27)/$F$27 -> 0.63344429 | H15: ='Costos Insumos'!$E$5*G15 -> 11433.669 | I15: =(G15*1000)*2.5% -> 15.836107 | J15: =((G15*1000)*2.5%)*'Costos Insumos'!$E$2 -> 601.77208 | K15: =('Costos Insumos'!$E$8*0.5)+(67*4) -> 3335.5 | L15: 119.08 | N15: =E15+H15+K15+L15 -> 35767.245 | O15: 0.68 | P15: =N15/(1-O15) -> 111772.64 | Q15: 0.4 | R15: =P15/(1-Q15) -> 186287.74 | S15: =(P15/0.75)*1.19 -> 177345.93
B16: LVR VERSA 55X50 - REAL | C16: 3416000 | D16: 9.5 | E16: =D16*'Costos Insumos'!$E$4 -> 23927.46 | F16: 482700 | G16: 0.6 | H16: ='Costos Insumos'!$E$5*G16 -> 10830 | I16: =(G16*1000)*2.5% -> 15 | J16: =((G16*1000)*2.5%)*'Costos Insumos'!$E$2 -> 570 | K16: =('Costos Insumos'!$E$8*0.5)+(67*4) -> 3335.5 | L16: 119.08 | N16: =E16+H16+K16+L16 -> 38212.04 | O16: 0.68 | P16: =N16/(1-O16) -> 119412.63 | Q16: 0.4 | R16: =P16/(1-Q16) -> 199021.04 | S16: =(P16/0.75)*1.19 -> 189468.03
B17: Lavarropas Versa 50X50 - REAL | C17: 3131000 | D17: 8 | E17: =D17*'Costos Insumos'!$E$4 -> 20149.44 | F17: 432900 | G17: 0.42 | H17: ='Costos Insumos'!$E$5*G17 -> 7581 | I17: =(G17*1000)*2.5% -> 10.5
B18: Meson VERSA 150x55 con Perf Cub (CALCULO 3D) | C18: 6116000 | D18: =(C18*$D$27)/$C$27 -> 14.841788 | E18: =D18*'Costos Insumos'!$E$4 -> 37381.715 | F18: 806900 | G18: =(F18*$G$27)/$F$27 -> 1.05889 | H18: ='Costos Insumos'!$E$5*G18 -> 19112.964 | I18: =(G18*1000)*2.5% -> 26.47225 | J18: =((G18*1000)*2.5%)*'Costos Insumos'!$E$2 -> 1005.9455 | K18: 12000 | L18: 125 | N18: =E18+H18+K18+L18 -> 68619.68 | O18: 0.68 | P18: =N18/(1-O18) -> 214436.5 | Q18: 0.4 | R18: =P18/(1-Q18) -> 357394.16 | S18: =(P18/0.75)*1.19 -> 340239.24
B19: MESON COCINA VERSA 150X55 BLANCO FORT-SIN PERF CUB-SIN PERF GRIF (3D) | C19: 6596000 | D19: =(C19*$D$27)/$C$27 -> 16.006611 | E19: =D19*'Costos Insumos'!$E$4 -> 40315.532 | F19: 1055000 | G19: =(F19*$G$27)/$F$27 -> 1.3844701 | H19: ='Costos Insumos'!$E$6*G19 -> 27865.23 | I19: =(G19*1000)*2.5% -> 34.611753 | J19: =((G19*1000)*2.5%)*'Costos Insumos'!$E$2 -> 1315.2466 | K19: 12000 | L19: 125 | N19: =E19+H19+K19+L19 -> 80305.762 | O19: 0.68 | P19: =N19/(1-O19) -> 250955.51 | Q19: 0.4 | R19: =P19/(1-Q19) -> 418259.18 | S19: =(P19/0.75)*1.19 -> 398182.74
A20: VCOC05-0024-SCG-0508 | B20: MESON COCINA VERSA 150X55 BLANCO FORT-SIN PERF CUB-SIN PERF GRIF (REAL) | C20: 6596000 | D20: 19.8 | E20: =D20*'Costos Insumos'!$E$4 -> 49869.864 | F20: 1055000 | G20: 1.4 | H20: ='Costos Insumos'!$E$6*G20 -> 28177.8 | I20: =(G20*1000)*2.5% -> 35 | J20: =((G20*1000)*2.5%)*'Costos Insumos'!$E$3 -> 1232 | K20: =('Costos Insumos'!$E$8)+('Costos Insumos'!$E$20*4) -> 6412.2 | L20: ='Costos Insumos'!E19 -> 135 | M20: ='Costos Insumos'!$E$26*29 -> 303.34 | N20: =E20+H20+J20+K20+L20+M20 -> 86130.204 | O20: 0.68 | P20: =N20/(1-O20) -> 269156.89 | Q20: 0.4 | R20: =P20/(1-Q20) -> 448594.81 | S20: =(P20/0.75)*1.19 -> 427062.26
A21: VCOC05-0024-SCG-0508 | B21: MESON COCINA VERSA 150X55 BLANCO FORT-SIN PERF CUB-SIN PERF GRIF (BOWL +3CM Profundidad) | C21: 6802000 | D21: =(C21*$D$20)/$C$20 -> 20.418375 | E21: =D21*'Costos Insumos'!$E$4 -> 51427.352 | F21: 1086000 | G21: =(F21*$G$20)/$F$20 -> 1.4411374 | H21: ='Costos Insumos'!$E$6*G21 -> 29005.773 | I21: =(G21*1000)*2.5% -> 36.028436 | J21: =((G21*1000)*2.5%)*'Costos Insumos'!$E$3 -> 1268.2009 | K21: ='Costos Insumos'!$E$8+('Costos Insumos'!$E$20*4)+('Costos Insumos'!$E$22*14) -> 13972.2 | L21: ='Costos Insumos'!E19 -> 135 | M21: ='Costos Insumos'!$E$26*29 -> 303.34 | N21: =E21+H21+J21+K21+L21+M21 -> 96111.866 | O21: 0.68 | P21: =N21/(1-O21) -> 300349.58 | Q21: 0.4 | R21: =P21/(1-Q21) -> 500582.64 | S21: =(P21/0.75)*1.19 -> 476554.67
A22: VCOC05-0024-SCG-0508 | B22: MESON COCINA VERSA 150X55 BLANCO FORT-PERF CUB-SIN PERF GRIF (3D) | C22: 5323000 | D22: =(C22*$D$20)/$C$20 -> 15.978684 | E22: =D22*'Costos Insumos'!$E$4 -> 40245.192 | F22: 822900 | G22: 1.12 | H22: ='Costos Insumos'!$E$6*G22 -> 22542.24 | I22: =(G22*1000)*2.5% -> 28 | J22: =((G22*1000)*2.5%)*'Costos Insumos'!$E$3 -> 985.6 | K22: =K20 -> 6412.2 | L22: ='Costos Insumos'!E19 -> 135 | M22: ='Costos Insumos'!$E$26*29 -> 303.34 | N22: =E22+H22+J22+K22+L22+M22 -> 70623.572 | O22: 0.68 | P22: =N22/(1-O22) -> 220698.66 | Q22: 0.4 | R22: =P22/(1-Q22) -> 367831.1 | S22: =(P22/0.75)*1.19 -> 350175.21
B23: Meson Eco 150x55 sin Perf Cub (CALCULO 3D) | C23: 8846000 | D23: =(C23*$D$27)/$C$27 -> 21.46672 | E23: =D23*'Costos Insumos'!$E$4 -> 54067.798 | F23: 1022000 | G23: =(F23*$G$27)/$F$27 -> 1.3411644 | H23: ='Costos Insumos'!$E$5*G23 -> 24208.018 | I23: =(G23*1000)*2.5% -> 33.529111 | J23: =((G23*1000)*2.5%)*'Costos Insumos'!$E$2 -> 1274.1062 | K23: 2000 | L23: 125 | N23: =E23+H23+K23+L23 -> 80400.816 | O23: 0.68 | P23: =N23/(1-O23) -> 251252.55 | Q23: 0.4 | R23: =P23/(1-Q23) -> 418754.25 | S23: =(P23/0.75)*1.19 -> 398654.05
A24: VCOC05-0007-SCG-0508 | B24: MESON COCINA ECO 150X55 BLANCO FORT-SIN PERF CUB-SIN PERF GRIF (REAL) | C24: 9743000 | D24: 20 | E24: =D24*'Costos Insumos'!$E$4 -> 50373.6 | F24: 1078000 | G24: 1.45 | H24: ='Costos Insumos'!$E$6*G24 -> 29184.15 | I24: =(G24*1000)*2.5% -> 36.25 | J24: =((G24*1000)*2.5%)*'Costos Insumos'!$E$3 -> 1276 | K24: ='Costos Insumos'!E23 -> 4292.53 | L24: ='Costos Insumos'!E19 -> 135 | N24: =E24+H24+K24+L24+J24 -> 85261.28 | O24: 0.68 | P24: =N24/(1-O24) -> 266441.5 | Q24: 0.4 | R24: =P24/(1-Q24) -> 444069.17 | S24: =(P24/0.75)*1.19 -> 422753.85
B25: Meson Eco 150x55 con Perf Cub - Calculo 3D | C25: 7468000 | D25: =(C25*$D$27)/$C$27 -> 18.122707 | E25: =D25*'Costos Insumos'!$E$4 -> 45645.299 | F25: 1022000 | G25: =(F25*$G$27)/$F$27 -> 1.3411644 | H25: ='Costos Insumos'!$E$6*G25 -> 26993.616 | I25: =(G25*1000)*2.5% -> 33.529111 | J25: =((G25*1000)*2.5%)*'Costos Insumos'!$E$3 -> 1180.2247 | K25: 2000 | L25: 125 | N25: =E25+H25+K25+L25 -> 74763.916 | O25: 0.68 | P25: =N25/(1-O25) -> 233637.24 | Q25: 0.4 | R25: =P25/(1-Q25) -> 389395.39 | S25: =(P25/0.75)*1.19 -> 370704.41
A26: VCOC05-0007-SNG-0508 | B26: MESON COCINA ECO 150X55 BLANCO FORT-PERF CUB-SIN PERF GRIF (REAL) | C26: 7468000 | D26: 23 | E26: =D26*'Costos Insumos'!$E$4 -> 57929.64 | F26: 1053000 | G26: 1.5 | H26: ='Costos Insumos'!$E$6*G26 -> 30190.5 | I26: =(G26*1000)*2.5% -> 37.5 | J26: =((G26*1000)*2.5%)*'Costos Insumos'!$E$3 -> 1320 | K26: ='Costos Insumos'!E23 -> 4292.53 | L26: ='Costos Insumos'!E19 -> 135 | M26: ='Costos Insumos'!E26*10 -> 104.6 | N26: =E26+H26+K26+L26+J26+M26 -> 93972.27 | O26: 0.68 | P26: =N26/(1-O26) -> 293663.34 | Q26: 0.4 | R26: =P26/(1-Q26) -> 489438.91 | S26: =(P26/0.75)*1.19 -> 465945.84
B27: PROMEDIO | C27: =AVERAGE(C3,C5,C7,C9,C16,C17,C24) -> 3396714.3 | D27: =AVERAGE(D3,D5,D7,D9,D16,D17,D24) -> 8.2428571 | E27: =AVERAGE(E3,E5,E7,E9,E16,E17,E24) -> 20761.119 | F27: =AVERAGE(F3,F5,F7,F9,F16,F17,F24) -> 446328.57 | G27: =AVERAGE(G3,G5,G7,G9,G16,G17,G24) -> 0.58571429 | H27: =AVERAGE(H3,H5,H7,H9,H16,H17,H24) -> 11002.379 | I27: =AVERAGE(I3,I5,I7,I9,I16,I17,I24) -> 14.642857 | J27: =AVERAGE(J3,J5,J7,J9,J16,J17,J24) -> 565.75 | ... L27: =AVERAGE(L3,L5,L7,L9,L16,L17,L24) -> 120.945 | N27: =AVERAGE(N3,N5,N7,N9,N16,N17,N24) -> 36483.625 | O27: =AVERAGE(O3,O5,O7,O9,O16,O17,O24) -> 0.74633333 | P27: =AVERAGE(P3,P5,P7,P9,P16,P17,P24) -> 137979.62 | Q27: =AVERAGE(Q3,Q5,Q7,Q9,Q16,Q17,Q24) -> 0.4 | R27: =AVERAGE(R3,R5,R7,R9,R16,R17,R24) -> 229966.03 | S27: =AVERAGE(S3,S5,S7,S9,S16,S17,S24) -> 218927.66
B28: LAVAMANOS SIENA 124X48 1 BOWL IZQ/DER | C28: 6334000 | D28: =(C28*$D$27)/$C$27 -> 15.370812 | E28: =D28*'Costos Insumos'!$E$4 -> 38714.157 | F28: 859800 | G28: =(F28*$G$27)/$F$27 -> 1.1283103 | H28: ='Costos Insumos'!$E$6*G28 -> 22709.502 | I28: =(G28*1000)*2.5% -> 28.207759 | J28: =((G28*1000)*2.5%)*'Costos Insumos'!$E$3 -> 992.9131 | K28: ='Costos Insumos'!E39 -> 11919 | L28: 135 | N28: =E28+H28+K28+L28+J28 -> 74470.572
B29: LAVAPLATO KOA 33INX22IN (3D) | C29: 5188000 | D29: =(C29*$D$27)/$C$27 -> 12.589797 | E29: =D29*'Costos Insumos'!$E$4 -> 31709.67 | F29: 842500 | G29: =(F29*$G$27)/$F$27 -> 1.1056077 | H29: ='Costos Insumos'!$E$6*G29 -> 22252.565 | I29: =(G29*1000)*2.5% -> 27.640191 | J29: =((G29*1000)*2.5%)*'Costos Insumos'!$E$3 -> 972.93474 | K29: 25000 | L29: 135 | N29: =E29+H29+K29+L29+J29 -> 80070.17 | O29: 0.68 | P29: =N29/(1-O29) -> 250219.28 | Q29: 0.4 | R29: =P29/(1-Q29) -> 417032.13 | S29: =(P29/0.75)*1.19 -> 397014.59

Sheet Fibra de vidrio Faldones
A1: Costo TUERCA 12MM P1.75 HEXAGONAL PARA HERRAJES | B1: 234.1
A2: Costo TORNILLO ENSAMBLE 6X1IN | B2: 18.53
A3: Costo TAPA TORNILLO PLAST 9MM (DAMA SENCILLA) BLANCA | B3: 16.81
A4: Costo SNAP FIJACION FALDON | B4: 1120.14
A5: Costo L FIJACION FALDON ACH (UND) | B5: 923.38
A6: Costo TUBO C18 3/4IN MECANICO CUADRADO GALVANIZADO (MT) | B6: =2618.72+525 -> 3143.72
A7: Costo CARTON SINGLE FACE 20CM (MT) | B7: =284.04 -> 284.04
A8: Costo REFUERZO FIBRA VIDRIO CON RESINA CARGADA Y CATALIZADOR (KG) | B8: 8299.39
A9: Costo GELCOAT BLANCO 898GC/ 5-2899W (KG) | B9: 18050
A10: Costo PEROXIDO LUPEROX K12G (GR) | B10: 38.5
A11: Costo MASILLA PARA VACIADO (KG) | B11: 5298.78 | AA11: OTROS
B12: Área superficial (mm^2) | C12: Refuerzo FV + Resina Cargada + Catalizador (KG) | D12: Masilla para vaciado (KG) | E12: Costo conformación ($) | F12: Gelcoat (kg) | G12: Peroxido pintura (gr) | H12: Costo Pintura ($) | I12: Cartón single face (MT) | J12: Costo single face ($) | K12: Tubo 3/4 IN Galvanizado (MT) | L12: Costo estructura metálica ($) | M12: Ele fijación (UND) | N12: Snap fijación (UND) | O12: Dama sencilla (UND) | P12: Tornillo 1IN | Q12: Tuerca 12 mm (UND) | R12: Costo ensamble Faldón | S12: Costo otros | T12: Costo producto MP Apróximado sin MO ni CIF ($) | U12: MC% | V12: Precio Mínimo | W12: Descuento | X12: Precio Maximo | Y12: PVP | AA12: Peso neto (kg) | AB12: Peso bruto (kg)
A13: FALDON HONOLULU DERECHO 180x120 | B13: 1443000 | C13: 9.6 | D13: 0.51 | E13: =($C13*$B$8)+($D13*$B$11) -> 82376.522 | F13: 2.03 | G13: =(F13*1000)*2.5% -> 50.75 | H13: =($B$9*$F13)+($B$10*$G13) -> 38595.375 | I13: 4 | J13: =$I13*$B$7 -> 1136.16 | K13: 0 | L13: =$K13*$B$6 -> 0 | M13: 6 | N13: 4 | O13: 6 | P13: 6 | Q13: =M13*2 -> 12 | R13: =(M13*$B$5)+(N13*$B$4)+(O13*$B$3)+(P13*$B$2)+(Q13*$B$1) -> 13042.08 | S13: 0 | T13: =L13+J13+H13+E13+R13+S13 -> 135150.14 | U13: 0.75 | V13: =T13/(1-U13) -> 540600.55 | W13: 0.4 | X13: =V13/(1-W13) -> 901000.91 | Y13: =(V13/0.75)*1.19 -> 857752.87
A14: FALDON QATAR BLANCO 180X100 | B14: 1573000 | C14: 14.1 | D14: 0.51 | E14: =($C14*$B$8)+($D14*$B$11) -> 119723.78 | F14: 1.5 | G14: =(F14*1000)*2.5% -> 37.5 | H14: =($B$9*$F14)+($B$10*$G14) -> 28518.75 | I14: 4 | J14: =$I14*$B$7 -> 1136.16 | K14: 0 | L14: =$K14*$B$6 -> 0 | M14: 9 | N14: 9 | O14: 9 | P14: 9 | Q14: =M14*2 -> 18 | R14: =(M14*$B$5)+(N14*$B$4)+(O14*$B$3)+(P14*$B$2)+(Q14*$B$1) -> 22923.54 | S14: 0 | T14: =L14+J14+H14+E14+R14+S14 -> 172302.23 | U14: 0.75 | V14: =T14/(1-U14) -> 689208.91 | W14: 0.4 | X14: =V14/(1-W14) -> 1148681.5 | Y14: =(V14/0.75)*1.19 -> 1093544.8
A15: FALDON NORUEGA BLANCO 156 | B15: 2879000 | C15: 12.43 | D15: 0.63 | E15: =($C15*$B$8)+($D15*$B$11) -> 106499.65 | F15: 5.11 | G15: =(F15*1000)*2.5% -> 127.75 | H15: =($B$9*$F15)+($B$10*$G15) -> 97153.875 | I15: 4 | J15: =$I15*$B$7 -> 1136.16 | K15: 0 | L15: =$K15*$B$6 -> 0 | M15: 0 | N15: 0 | O15: 0 | P15: 0 | Q15: 0 | R15: =(M15*$B$5)+(N15*$B$4)+(O15*$B$3)+(P15*$B$2)+(Q15*$B$1) -> 0 | S15: 0 | T15: =L15+J15+H15+E15+R15+S15 -> 204789.68 | U15: 0.75 | V15: =T15/(1-U15) -> 819158.74 | W15: 0.4 | X15: =V15/(1-W15) -> 1365264.6 | Y15: =(V15/0.75)*1.19 -> 1299731.9
A16: FALDON MILENIUM PLUS (2 PARTES) BLANCO 182X123 | B16: =697100+1057000 -> 1754100 | C16: 5.9 | D16: 0.48 | E16: =($C16*$B$8)+($D16*$B$11) -> 51509.815 | F16: 1.4 | G16: =(F16*1000)*2.5% -> 35 | H16: =($B$9*$F16)+($B$10*$G16) -> 26617.5 | I16: 4 | J16: =$I16*$B$7 -> 1136.16 | K16: 4 | L16: =$K16*$B$6 -> 12574.88 | M16: 9 | N16: 3 | O16: 9 | P16: 9 | Q16: =48-28 -> 20 | R16: =(M16*$B$5)+(N16*$B$4)+(O16*$B$3)+(P16*$B$2)+(Q16*$B$1) -> 16670.9 | S16: 0 | T16: =L16+J16+H16+E16+R16+S16 -> 108509.26 | U16: 0.75 | V16: =T16/(1-U16) -> 434037.02 | W16: 0.4 | X16: =V16/(1-W16) -> 723395.04 | Y16: =(V16/0.75)*1.19 -> 688672.07
A17: PROMEDIO CONSUMO FALDONES | B17: =AVERAGE(B13:B16) -> 1912275 | C17: =AVERAGE(C13:C16) -> 10.5075 | D17: =AVERAGE(D13:D16) -> 0.5325 | E17: =AVERAGE(E13:E16) -> 90027.441 | F17: =AVERAGE(F13:F16) -> 2.51 | G17: =AVERAGE(G13:G16) -> 62.75 | H17: =AVERAGE(H13:H16) -> 47721.375 | I17: =AVERAGE(I13:I16) -> 4 | J17: =AVERAGE(J13:J16) -> 1136.16
A18: FALDON SANTORINI PLUS BLANCO 180x180 | B18: =1597000 -> 1597000 | C18: =($B$18*C17)/$B$17 -> 8.7751383 | D18: =($B$18*D17)/$B$17 -> 0.44470722 | E18: =($C18*$B$8)+($D18*$B$11) -> 75184.7 | F18: =($B$18*F17)/$B$17 -> 2.0961786 | G18: =(F18*1000)*2.5% -> 52.404466 | H18: =($B$9*$F18)+($B$10*$G18) -> 39853.596 | I18: =($B$18*I17)/$B$17 -> 3.3405237 | J18: =$I18*$B$7 -> 948.84236 | K18: =((165.5*2)+(60*4)+50+(48*3))/100 -> 7.65 | L18: =$K18*$B$6 -> 24049.458 | M18: =4*4 -> 16 | N18: =2*4 -> 8 | O18: =M18 -> 16 | P18: =M18 -> 16 | Q18: =M18*2 -> 32 | R18: =(M18*$B$5)+(N18*$B$4)+(O18*$B$3)+(P18*$B$2)+(Q18*$B$1) -> 31791.84 | S18: =12000+10000+20000 -> 42000 | T18: =L18+J18+H18+E18+R18+S18 -> 213828.44 | U18: 0.75 | V18: =T18/(1-U18) -> 855313.75 | W18: 0.4 | X18: =V18/(1-W18) -> 1425522.9 | Y18: =(V18/0.75)*1.19 -> 1357097.8

Sheet Fibra de vidrio bañeras Indoor
A1: Costo TUERCA 12MM P1.75 HEXAGONAL PARA HERRAJES | B1: 234.1
A2: Costo TORNILLO ENSAMBLE 6X1IN | B2: 18.53
A3: Costo TAPA TORNILLO PLAST 9MM (DAMA SENCILLA) BLANCA | B3: 16.81
A4: Costo SNAP FIJACION FALDON | B4: 1120.14
A5: Costo L FIJACION FALDON ACH (UND) | B5: 923.38
A6: Costo TUBO C18 3/4IN MECANICO CUADRADO GALVANIZADO (MT) | B6: =2618.72+525 -> 3143.72
A7: Costo CARTON SINGLE FACE 20CM (MT) | B7: =284.04 -> 284.04
A8: Costo REFUERZO FIBRA VIDRIO CON RESINA CARGADA Y CATALIZADOR (KG) | B8: 8299.39
A9: Costo GELCOAT BLANCO 898GC/ 5-2899W (KG) | B9: 18050
A10: Costo PEROXIDO LUPEROX K12G (GR) | B10: 38.5
A11: Costo MASILLA PARA VACIADO (KG) | B11: 5298.78
B12: Área superficial (mm^2) | C12: Refuerzo FV + Resina SIN carga + Catalizador (KG) | D12: Masilla para vaciado (KG) | E12: Costo conformación ($) | F12: Gelcoat (kg) | G12: Peroxido pintura (gr) | H12: Costo Pintura ($) | I12: Cartón single face (MT) | J12: Costo single face ($) | K12: Tubo 3/4 IN Galvanizado (MT) | L12: Costo estructura metálica ($) | M12: Ele fijación (UND) | N12: Snap fijación (UND) | O12: Dama sencilla (UND) | P12: Tornillo 1IN | Q12: Tuerca 12 mm (UND) | R12: Costo ensamble Faldón | S12: Costo otros | T12: Costo producto MP Apróximado sin MO ni CIF ($) | U12: MC% | V12: Precio Mínimo | W12: Descuento | X12: Precio Maximo | Y12: PVP
A13: HIDROMASAJE HONOLULU DERECHA 180X120 BLANCO | B13: 3384000 | C13: 24.34 | D13: 0.51 | E13: =($C13*$B$8)+($D13*$B$11) -> 204709.53 | F13: 5.51 | G13: =(F13*1000)*2.5% -> 137.75 | H13: =($B$9*$F13)+($B$10*$G13) -> 104758.88
A14: HIDROMASAJE TAHITI 152X152 BLANCO | B14: 3564000 | C14: 19.18 | D14: 0.67 | E14: =($C14*$B$8)+($D14*$B$11) -> 162732.48 | F14: 4.62 | G14: =(F14*1000)*2.5% -> 115.5 | H14: =($B$9*$F14)+($B$10*$G14) -> 87837.75
A15: HIDROMASAJE NORUEGA 156 BLANCO | B15: 3407000 | C15: 20 | D15: 0.22 | E15: =($C15*$B$8)+($D15*$B$11) -> 167153.53 | F15: 4.85 | G15: =(F15*1000)*2.5% -> 121.25 | H15: =($B$9*$F15)+($B$10*$G15) -> 92210.625 | I15: 4.02 | J15: =$I15*$B$7 -> 1141.8408 | K15: 0 | L15: =$K15*$B$6 -> 0 | M15: 0 | N15: 0 | O15: 0 | P15: 0 | Q15: 0 | R15: =(M15*$B$5)+(N15*$B$4)+(O15*$B$3)+(P15*$B$2)+(Q15*$B$1) -> 0 | S15: 0 | T15: =L15+J15+H15+E15+R15+S15 -> 260506 | U15: 0.75 | V15: =T15/(1-U15) -> 1042024 | W15: 0.4 | X15: =V15/(1-W15) -> 1736706.6 | Y15: =(V15/0.75)*1.19 -> 1653344.7
A16: HIDROMASAJE DANESA 189x113 BLANCO | B16: 3268000 | C16: 22.3 | D16: 0.33 | E16: =($C16*$B$8)+($D16*$B$11) -> 186824.99 | F16: 5.1 | G16: =(F16*1000)*2.5% -> 127.5 | H16: =($B$9*$F16)+($B$10*$G16) -> 96963.75 | I16: 6.94 | J16: =$I16*$B$7 -> 1971.2376
A17: HIDROMASAJE SANTORINI 180X180 | B17: 6311000 | C17: 48.4 | D17: 0.97 | E17: =($C17*$B$8)+($D17*$B$11) -> 406830.29 | F17: 8.5 | G17: =(F17*1000)*2.5% -> 212.5 | H17: =($B$9*$F17)+($B$10*$G17) -> 161606.25 | I17: 14 | J17: =$I17*$B$7 -> 3976.56
A18: PROMEDIO CONSUMO HIDROS | B18: =AVERAGE(B13:B17) -> 3986800 | C18: =AVERAGE(C13:C17) -> 26.844 | D18: =AVERAGE(D13:D17) -> 0.54 | E18: =AVERAGE(E13:E17) -> 225650.17 | F18: =AVERAGE(F13:F17) -> 5.716 | G18: =AVERAGE(G13:G16) -> 125.5 | H18: =AVERAGE(H13:H17) -> 108675.45 | I18: =AVERAGE(I13:I17) -> 8.32 | J18: =AVERAGE(J13:J16) -> 1556.5392
A19: HIDROMASAJE MYDAS 182 BLANCO | B19: 4506000 | C19: =(B19*$C$18)/$B$18 -> 30.339888 | D19: =(B19*$D$18)/$B$18 -> 0.61032407 | E19: =($C19*$B$8)+($D19*$B$11) -> 255036.53 | F19: =(B19*$F$18)/$B$18 -> 6.4603933 | G19: =(F19*1000)*2.5% -> 161.50983 | H19: =($B$9*$F19)+($B$10*$G19) -> 122828.23 | I19: =($B$19*I18)/$B$18 -> 9.4035116 | J19: =$I19*$B$7 -> 2670.9734 | K19: =((165.5*2)+(60*4)+50+(48*3))/100 -> 7.65 | L19: =$K19*$B$6 -> 24049.458 | M19: =4*4 -> 16 | N19: =2*4 -> 8 | O19: =M19 -> 16 | P19: =M19 -> 16 | Q19: =M19*2 -> 32 | R19: =(M19*$B$5)+(N19*$B$4)+(O19*$B$3)+(P19*$B$2)+(Q19*$B$1) -> 31791.84 | S19: =12000+10000+20000 -> 42000 | T19: =L19+J19+H19+E19+R19+S19 -> 478377.03 | U19: 0.75 | V19: =T19/(1-U19) -> 1913508.1 | W19: 0.4 | X19: =V19/(1-W19) -> 3189180.2 | Y19: =(V19/0.75)*1.19 -> 3036099.6
A20: HIDROMASAJE IBIZA 182X100 BLANCO-CONSTRU | B20: 3415000 | C20: =(B20*$C$18)/$B$18 -> 22.993945 | D20: =(B20*$D$18)/$B$18 -> 0.46255142 | E20: =($C20*'Costos Insumos'!$E$35)+($D20*$B$11) -> 209050.86 | F20: =(B20*$F$18)/$B$18 -> 4.8961924 | G20: =(F20*1000)*2.5% -> 122.40481 | H20: =($B$9*$F20)+($B$10*$G20) -> 93088.859 | I20: =($B$19*I19)/$B$18 -> 10.628129 | J20: =$I20*$B$7 -> 3018.8137 | K20: =((165.5*2)+(60*4)+50+(48*3))/100 -> 7.65 | L20: =$K20*$B$6 -> 24049.458 | M20: =4*4 -> 16 | N20: =2*4 -> 8 | O20: =M20 -> 16 | P20: =M20 -> 16 | Q20: =M20*2 -> 32 | R20: =(M20*$B$5)+(N20*$B$4)+(O20*$B$3)+(P20*$B$2)+(Q20*$B$1) -> 31791.84 | S20: =12000+10000+20000 -> 42000 | T20: =L20+J20+H20+E20+R20+S20 -> 402999.83
A21: HIDROMASAJE IBIZA 195X165 BLANCO | B21: 5223000 | C21: =(B21*$C$18)/$B$18 -> 35.167606 | D21: =(B21*$D$18)/$B$18 -> 0.70743955 | E21: =($C21*'Costos Insumos'!$E$35)+($D21*$B$11) -> 319728.45 | F21: =(B21*$F$18)/$B$18 -> 7.4883786 | G21: =(F21*1000)*2.5% -> 187.20947 | H21: =($B$9*$F21)+($B$10*$G21) -> 142372.8 | I21: =($B$19*I20)/$B$18 -> 12.012227 | J21: =$I21*$B$7 -> 3411.953 | K21: =((165.5*2)+(60*4)+50+(48*3))/100 -> 7.65 | L21: =$K21*$B$6 -> 24049.458 | M21: =4*4 -> 16 | N21: =2*4 -> 8 | O21: =M21 -> 16 | P21: =M21 -> 16 | Q21: =M21*2 -> 32 | R21: =(M21*$B$5)+(N21*$B$4)+(O21*$B$3)+(P21*$B$2)+(Q21*$B$1) -> 31791.84 | S21: =12000+10000+20000 -> 42000 | T21: =L21+J21+H21+E21+R21+S21 -> 563354.5
B29: Cuerpos (1)
B30: Área | C30: 5223000
B31: Densidad | C31: 0.008 g / mm^3
B32: Masa | C32: 0.00 g
B33: Volumen | C33: 0.00 mm^3
B34: Material físico | C34: Acero
B35: Aspecto | C35: Acero - Satinado
B37: Cuadro delimitador
C38: Longitud | D38: 1950.00 mm
C39: Anchura | D39: 1650.00 mm
C40: Altura | D40: 515.00 mm
B41: Centro de masa | C41: 0.00 mm, 0.00 mm, 0.00 mm
B43: Momento de inercia en el centro de masa (g mm^2)
C44: Ixx = 0.00
C45: Ixy = 0.00
C46: Ixz = 0.00
C47: Iyx = 0.00
C48: Iyy = 0.00
C49: Iyz = 0.00
...
